Workbook
Name Slicer_Country: #N/A

Sheet NZ staff
C1: Employee Data
C5: Name | D5: Gender | E5: Department | F5: Age | G5: Date Joined | H5: Salary | I5: Rating
C6: Lindy Guillet | D6: Male | E6: Sales | F6: 22 | G6: 44446 | H6: 112780 | I6: Above average
C7: Ambros Murthwaite | D7: Male | E7: Procurement | F7: 46 | G7: 44758 | H7: 70610 | I7: Average
C8: Tatum Hush | D8: Female | E8: Sales | F8: 28 | G8: 44357 | H8: 53240 | I8: Average
C9: Benny Karolovsky | E9: Finance | F9: 37 | G9: 44146 | H9: 115440 | I9: Poor
C10: Hoyt D'Alesco | D10: Male | E10: Sales | F10: 32 | G10: 44465 | H10: 53540 | I10: Average
C11: Halimeda Kuscha | D11: Female | E11: Procurement | F11: 30 | G11: 44861 | H11: 112570 | I11: Average
C12: Erin Androsik | D12: Male | E12: Procurement | F12: 33 | G12: 44701 | H12: 48530 | I12: Above average
C13: Vic Radolf | D13: Female | E13: Website | F13: 24 | G13: 44148 | H13: 62780 | I13: Average
C14: William Reeveley | D14: Male | E14: Website | F14: 33 | G14: 44509 | H14: 53870 | I14: Average
C15: Ewart Laphorn | D15: Female | E15: HR | F15: 27 | G15: 44122 | H15: 119110 | I15: Average
C16: Bev Lashley | D16: Male | E16: Website | F16: 29 | G16: 44180 | H16: 112110 | I16: Poor
C17: Kath Bletsoe | D17: Male | E17: Sales | F17: 25 | G17: 44383 | H17: 65700 | I17: Average
C18: Murry Dryburgh | D18: Male | E18: Website | F18: 37 | G18: 44701 | H18: 69070 | I18: Average
C19: Kaine Padly | D19: Male | E19: Website | F19: 20 | G19: 44459 | H19: 107700 | I19: Average
C20: Kassi Jonson | D20: Female | E20: Website | F20: 32 | G20: 44354 | H20: 43840 | I20: Above average
C21: Simon Kembery | D21: Male | E21: Procurement | F21: 40 | G21: 44263 | H21: 99750 | I21: Average
... C29: Esmaria Denecamp | D29: Male | E29: Finance | F29: 27 | G29: 44567 | H29: 48980 | I29: Average
C30: Curtice Advani | E30: Finance | F30: 30 | G30: 44597 | H30: 64000 | I30: Average
C31: Barr Faughny | D31: Female | E31: Procurement | F31: 42 | G31: 44779 | H31: 75000 | I31: Exceptional
C32: Merrilee Plenty | D32: Female | E32: Website | F32: 40 | G32: 44337 | H32: 87620 | I32: Average
C33: Niall Selesnick | D33: Female | E33: Website | F33: 29 | G33: 44023 | H33: 34980 | I33: Average
C34: Beverie Moffet | D34: Female | E34: Finance | F34: 28 | G34: 44185 | H34: 75970 | I34: Average
C35: Jehu Rudeforth | D35: Female | E35: Finance | F35: 34 | G35: 44612 | H35: 60130 | I35: Average
C36: Camilla Castle | D36: Female | E36: Website | F36: 33 | G36: 44374 | H36: 75480 | I36: Very poor
C37: Roddy Speechley | D37: Male | E37: Procurement | F37: 33 | G37: 44164 | H37: 115920 | I37: Average
C38: Gray Seamon | D38: Female | E38: Sales | F38: 36 | G38: 44494 | H38: 78540 | I38: Average
C39: Madelene Upcott | D39: Male | E39: Procurement | F39: 25 | G39: 44726 | H39: 109190 | I39: Above average
C40: Violante Courtonne | D40: Female | E40: Sales | F40: 34 | G40: 44721 | H40: 49630 | I40: Poor
C41: Bernie Gorges | D41: Female | E41: Procurement | F41: 28 | G41: 44630 | H41: 99970 | I41: Average
C42: Torrance Collier | D42: Female | E42: Website | F42: 33 | G42: 44190 | H42: 96140 | I42: Average
... C67: Wilone O'Kielt | D67: Female | E67: Website | F67: 43 | G67: 45045 | H67: 114870 | I67: Average
C68: Madge McCloughen | E68: Website | F68: 32 | G68: 44774 | H68: 91310 | I68: Average
C69: Janene Hairsine | D69: Female | E69: Procurement | F69: 28 | G69: 44486 | H69: 104770 | I69: Average
C70: Alta Kaszper | D70: Male | E70: Sales | F70: 27 | G70: 44134 | H70: 54970 | I70: Average
C71: Dennison Crosswaite | E71: Website | F71: 26 | G71: 44271 | H71: 90700 | I71: Above average
C72: Oran Buxcy | D72: Female | E72: Sales | F72: 38 | G72: 44329 | H72: 56870 | I72: Above average
C73: Hinda Label | D73: Female | E73: Sales | F73: 25 | G73: 44205 | H73: 92700 | I73: Average
C74: Marney O'Breen | D74: Female | E74: Finance | F74: 21 | G74: 44317 | H74: 65920 | I74: Average
...

Sheet India Staff
B2: Name | C2: Gender | D2: Age | E2: Rating | F2: Date Joined | G2: Department | H2: Salary
B3: Deepali Charan | C3: Male | D3: 20 | E3: Average | F3: 44122 | G3: Website | H3: 112650
B4: Yagna Sujeev | C4: Female | D4: 32 | E4: Above average | F4: 44293 | G4: Website | H4: 43840
B5: Satyendra Venkatadri | C5: Male | D5: 31 | E5: Average | F5: 44663 | G5: Procurement | H5: 103550
B6: Madhavdas Buhpathi | C6: Female | D6: 32 | E6: Average | F6: 44339 | G6: HR | H6: 45510
B7: Sahila Chandrasekhar | D7: 37 | E7: Poor | F7: 44085 | G7: Finance | H7: 115440
B8: Mirium Seemantini Shivakumar | C8: Female | D8: 38 | E8: Above average | F8: 44268 | G8: Sales | H8: 56870
B9: Purnendu Vijayarangan | C9: Female | D9: 25 | E9: Average | F9: 44144 | G9: Sales | H9: 92700
B10: Rukma Vinita | D10: 32 | E10: Average | F10: 44713 | G10: Website | H10: 91310
B11: Yauvani Tarpa | C11: Male | D11: 33 | E11: Average | F11: 44324 | G11: Sales | H11: 74550
B12: Damayanti Thangavadivelu | C12: Male | D12: 25 | E12: Above average | F12: 44665 | G12: Procurement | H12: 109190
B13: Manjusri Ruchi | C13: Female | D13: 40 | E13: Average | F13: 44320 | G13: Website | H13: 104410
B14: Mithil Nadkarni | C14: Male | D14: 30 | E14: Average | F14: 44544 | G14: Finance | H14: 96800
B15: Ardhendu Abhichandra Jayakar | C15: Male | D15: 28 | E15: Above average | F15: 43980 | G15: Finance | H15: 48170
B16: Akbar Sorabhjee | C16: Male | D16: 21 | E16: Average | F16: 44042 | G16: Procurement | H16: 37920
B17: Bandhula Sathyanna | C17: Male | D17: 34 | E17: Average | F17: 44642 | G17: Procurement | H17: 112650
B18: Daruka Ghazali | C18: Female | D18: 34 | E18: Poor | F18: 44660 | G18: Sales | H18: 49630
B19: Heer Pennathur | C19: Male | D19: 36 | E19: Average | F19: 43958 | G19: Website | H19: 118840
B20: Shekhar Eswara | C20: Male | D20: 30 | E20: Average | F20: 44789 | G20: Website | H20: 69710
B21: Udyan Lanka | C21: Male | D21: 20 | E21: Average | F21: 44683 | G21: Procurement | H21: 79570
B22: Shreela Ramasubraman | C22: Female | D22: 22 | E22: Above average | F22: 44388 | G22: Procurement | H22: 76900
... B53: Indu Varada Sumedh | C53: Female | D53: 28 | E53: Average | F53: 44124 | G53: Finance | H53: 75970
B54: Karuna Pashupathy | D54: 27 | E54: Above average | F54: 44212 | G54: Website | H54: 90700
B55: Mardav Ramaswami | C55: Male | D55: 30 | E55: Average | F55: 44607 | G55: Procurement | H55: 60570
B56: Sarayu Ragunathan | C56: Male | D56: 33 | E56: Average | F56: 44103 | G56: Procurement | H56: 115920
B57: Kevalkumar Solanki | C57: Female | D57: 33 | E57: Average | F57: 44006 | G57: Finance | H57: 65360
B58: Upendra Swati | D58: 30 | E58: Average | F58: 44535 | G58: Finance | H58: 64000
B59: Deepit Ranjana | C59: Female | D59: 34 | E59: Average | F59: 44383 | G59: Finance | H59: 92450
B60: Amal Nimesh | C60: Male | D60: 31 | E60: Average | F60: 44450 | G60: Website | H60: 48950
B61: Kunja Prashanta Vibha | C61: Female | D61: 27 | E61: Average | F61: 44625 | G61: Website | H61: 83750
B62: Godavari Veena | C62: Female | D62: 40 | E62: Average | F62: 44276 | G62: Website | H62: 87620
B63: Devasree Fullara Saurin | C63: Female | D63: 20 | E63: Poor | F63: 44476 | G63: Sales | H63: 68900
B64: Geena Raghavanpillai | C64: Male | D64: 32 | E64: Average | F64: 44403 | G64: Sales | H64: 53540
B65: Rupak Mehra | C65: Male | D65: 28 | E65: Very poor | F65: 44758 | G65: Sales | H65: 43510
B66: Sawini Chandan | C66: Female | D66: 38 | E66: Exceptional | F66: 44316 | G66: Sales | H66: 109160
B67: Baruna Ogale | C67: Male | D67: 40 | E67: Average | F67: 44204 | G67: Procurement | H67: 99750
B68: Jagajeet Viraj | C68: Female | D68: 31 | E68: Average | F68: 44084 | G68: Website | H68: 41980
B69: Kulbhushan Moorthy | C69: Male | D69: 36 | E69: Average | F69: 44272 | G69: Finance | H69: 71380
B70: Ilesh Dasgupta | C70: Male | D70: 27 | E70: Very poor | F70: 44547 | G70: Procurement | H70: 113280
... B98: Madhavdas Buhpathi | C98: Female | D98: 32 | E98: Average | F98: 44339 | G98: HR | H98: 45510
...

Sheet all Staff
A1: Name | B1: Gender | C1: Department | D1: Age | E1: Date Joined | F1: Salary | G1: Rating | H1: Country | I1: current date | J1: tunure | K1: tunure in year | L1: Bouns | M1: Rating in number | O1: 1
A2: Gretchen Callow | B2: Female | C2: Website | D2: 21 | E2: 44678 | F2: 33920 | G2: Average | H2: NZ | I2: =TODAY() -> 45585 | J2: =All_Staff[[#This Row],[current date]]-All_Staff[[#This Row],[Date Joined]] -> 907 | K2: =All_Staff[[#This Row],[tunure]]/365 -> 2.4849315 | L2: =IF(All_Staff[[#This Row],[tunure in year]]>3,3%,2%)*All_Staff[[#This Row],[Salary]] -> 678.4 | M2: =_xlfn.XLOOKUP(All_Staff[[#This Row],[Rating]],'Salary vs Rating.'!$B$3:$B$7,'Salary vs Rating.'!$C$3:$C$7) -> 3 | P2: count of employees | Q2: =COUNTA(A:A) -> 185
A3: Shubhra Potla | B3: Female | C3: Website | D3: 21 | E3: 44619 | F3: 33920 | G3: Average | H3: india | I3: =TODAY() -> 45585 | J3: =All_Staff[[#This Row],[current date]]-All_Staff[[#This Row],[Date Joined]] -> 966 | K3: =All_Staff[[#This Row],[tunure]]/365 -> 2.6465753 | L3: =IF(All_Staff[[#This Row],[tunure in year]]>3,3%,2%)*All_Staff[[#This Row],[Salary]] -> 678.4 | M3: =_xlfn.XLOOKUP(All_Staff[[#This Row],[Rating]],'Salary vs Rating.'!$B$3:$B$7,'Salary vs Rating.'!$C$3:$C$7) -> 3 | P3: average age | Q3: =AVERAGE(D:D) -> 30.445652
A4: Niall Selesnick | B4: Female | C4: Website | D4: 29 | E4: 44023 | F4: 34980 | G4: Average | H4: NZ | I4: =TODAY() -> 45585 | J4: =All_Staff[[#This Row],[current date]]-All_Staff[[#This Row],[Date Joined]] -> 1562 | K4: =All_Staff[[#This Row],[tunure]]/365 -> 4.2794521 | L4: =IF(All_Staff[[#This Row],[tunure in year]]>3,3%,2%)*All_Staff[[#This Row],[Salary]] -> 1049.4 | M4: =_xlfn.XLOOKUP(All_Staff[[#This Row],[Rating]],'Salary vs Rating.'!$B$3:$B$7,'Salary vs Rating.'!$C$3:$C$7) -> 3 | P4: average salary | Q4: =AVERAGE(F:F) -> 77366.522
A5: Suchira Bhanupriya Tapti | B5: Female | C5: Website | D5: 29 | E5: 43962 | F5: 34980 | G5: Average | H5: india | I5: =TODAY() -> 45585 | J5: =All_Staff[[#This Row],[current date]]-All_Staff[[#This Row],[Date Joined]] -> 1623 | K5: =All_Staff[[#This Row],[tunure]]/365 -> 4.4465753 | L5: =IF(All_Staff[[#This Row],[tunure in year]]>3,3%,2%)*All_Staff[[#This Row],[Salary]] -> 1049.4 | M5: =_xlfn.XLOOKUP(All_Staff[[#This Row],[Rating]],'Salary vs Rating.'!$B$3:$B$7,'Salary vs Rating.'!$C$3:$C$7) -> 3 | P5: average tunure | Q5: =AVERAGE(K:K) -> 3.1520548
A6: Bili Sizey | B6: Male | C6: Sales | D6: 43 | E6: 44620 | F6: 36040 | G6: Average | H6: NZ | I6: =TODAY() -> 45585 | J6: =All_Staff[[#This Row],[current date]]-All_Staff[[#This Row],[Date Joined]] -> 965 | K6: =All_Staff[[#This Row],[tunure]]/365 -> 2.6438356 | L6: =IF(All_Staff[[#This Row],[tunure in year]]>3,3%,2%)*All_Staff[[#This Row],[Salary]] -> 720.8 | M6: =_xlfn.XLOOKUP(All_Staff[[#This Row],[Rating]],'Salary vs Rating.'!$B$3:$B$7,'Salary vs Rating.'!$C$3:$C$7) -> 3 | P6: femal ratio | Q6: =Q9/Q2 -> 0.46486486
A7: Waheeda Vasuman | B7: Male | C7: Sales | D7: 43 | E7: 44558 | F7: 36040 | G7: Average | H7: india | I7: =TODAY() -> 45585 | J7: =All_Staff[[#This Row],[current date]]-All_Staff[[#This Row],[Date Joined]] -> 1027 | K7: =All_Staff[[#This Row],[tunure]]/365 -> 2.8136986 | L7: =IF(All_Staff[[#This Row],[tunure in year]]>3,3%,2%)*All_Staff[[#This Row],[Salary]] -> 720.8 | M7: =_xlfn.XLOOKUP(All_Staff[[#This Row],[Rating]],'Salary vs Rating.'!$B$3:$B$7,'Salary vs Rating.'!$C$3:$C$7) -> 3 | P7: median of age | Q7: =MEDIAN(D:D) -> 30
A8: Orton Livick | B8: Male | C8: Procurement | D8: 21 | E8: 44104 | F8: 37920 | G8: Average | H8: NZ | I8: =TODAY() -> 45585 | J8: =All_Staff[[#This Row],[current date]]-All_Staff[[#This Row],[Date Joined]] -> 1481 | K8: =All_Staff[[#This Row],[tunure]]/365 -> 4.0575342 | L8: =IF(All_Staff[[#This Row],[tunure in year]]>3,3%,2%)*All_Staff[[#This Row],[Salary]] -> 1137.6 | M8: =_xlfn.XLOOKUP(All_Staff[[#This Row],[Rating]],'Salary vs Rating.'!$B$3:$B$7,'Salary vs Rating.'!$C$3:$C$7) -> 3 | P8: median of salary | Q8: =MEDIAN(F:F) -> 75140
A9: Akbar Sorabhjee | B9: Male | C9: Procurement | D9: 21 | E9: 44042 | F9: 37920 | G9: Average | H9: india | I9: =TODAY() -> 45585 | J9: =All_Staff[[#This Row],[current date]]-All_Staff[[#This Row],[Date Joined]] -> 1543 | K9: =All_Staff[[#This Row],[tunure]]/365 -> 4.2273973 | L9: =IF(All_Staff[[#This Row],[tunure in year]]>3,3%,2%)*All_Staff[[#This Row],[Salary]] -> 1137.6 | M9: =_xlfn.XLOOKUP(All_Staff[[#This Row],[Rating]],'Salary vs Rating.'!$B$3:$B$7,'Salary vs Rating.'!$C$3:$C$7) -> 3 | P9: count of female | Q9: =COUNTIF(All_Staff[Gender],"Female") -> 86
A10: Archibald Filliskirk | B10: Male | C10: Procurement | D10: 35 | E10: 44727 | F10: 40400 | G10: Average | H10: NZ | I10: =TODAY() -> 45585 | J10: =All_Staff[[#This Row],[current date]]-All_Staff[[#This Row],[Date Joined]] -> 858 | K10: =All_Staff[[#This Row],[tunure]]/365 -> 2.3506849 | L10: =IF(All_Staff[[#This Row],[tunure in year]]>3,3%,2%)*All_Staff[[#This Row],[Salary]] -> 808 | M10: =_xlfn.XLOOKUP(All_Staff[[#This Row],[Rating]],'Salary vs Rating.'!$B$3:$B$7,'Salary vs Rating.'!$C$3:$C$7) -> 3
A11: Shobhana Samuel | B11: Male | C11: Procurement | D11: 35 | E11: 44666 | F11: 40400 | G11: Average | H11: india | I11: =TODAY() -> 45585 | J11: =All_Staff[[#This Row],[current date]]-All_Staff[[#This Row],[Date Joined]] -> 919 | K11: =All_Staff[[#This Row],[tunure]]/365 -> 2.5178082 | L11: =IF(All_Staff[[#This Row],[tunure in year]]>3,3%,2%)*All_Staff[[#This Row],[Salary]] -> 808 | M11: =_xlfn.XLOOKUP(All_Staff[[#This Row],[Rating]],'Salary vs Rating.'!$B$3:$B$7,'Salary vs Rating.'!$C$3:$C$7) -> 3 | P11: ratio of 90000$> | Q11: =Q13/Q12 -> 0.34782609
A12: Crissie Cordel | B12: Female | C12: Procurement | D12: 32 | E12: 44611 | F12: 41570 | G12: Average | H12: NZ | I12: =TODAY() -> 45585 | J12: =All_Staff[[#This Row],[current date]]-All_Staff[[#This Row],[Date Joined]] -> 974 | K12: =All_Staff[[#This Row],[tunure]]/365 -> 2.6684932 | L12: =IF(All_Staff[[#This Row],[tunure in year]]>3,3%,2%)*All_Staff[[#This Row],[Salary]] -> 831.4 | M12: =_xlfn.XLOOKUP(All_Staff[[#This Row],[Rating]],'Salary vs Rating.'!$B$3:$B$7,'Salary vs Rating.'!$C$3:$C$7) -> 3 | P12: count of salary | Q12: =COUNT(F:F) -> 184
A13: Prerana Nishita | B13: Female | C13: Procurement | D13: 32 | E13: 44549 | F13: 41570 | G13: Average | H13: india | I13: =TODAY() -> 45585 | J13: =All_Staff[[#This Row],[current date]]-All_Staff[[#This Row],[Date Joined]] -> 1036 | K13: =All_Staff[[#This Row],[tunure]]/365 -> 2.8383562 | L13: =IF(All_Staff[[#This Row],[tunure in year]]>3,3%,2%)*All_Staff[[#This Row],[Salary]] -> 831.4 | M13: =_xlfn.XLOOKUP(All_Staff[[#This Row],[Rating]],'Salary vs Rating.'!$B$3:$B$7,'Salary vs Rating.'!$C$3:$C$7) -> 3 | P13: count of 90000 | Q13: =COUNTIF(F:F,">90000") -> 64
A14: Dotty Strutley | B14: Female | C14: Website | D14: 31 | E14: 44145 | F14: 41980 | G14: Average | H14: NZ | I14: =TODAY() -> 45585 | J14: =All_Staff[[#This Row],[current date]]-All_Staff[[#This Row],[Date Joined]] -> 1440 | K14: =All_Staff[[#This Row],[tunure]]/365 -> 3.9452055 | L14: =IF(All_Staff[[#This Row],[tunure in year]]>3,3%,2%)*All_Staff[[#This Row],[Salary]] -> 1259.4 | M14: =_xlfn.XLOOKUP(All_Staff[[#This Row],[Rating]],'Salary vs Rating.'!$B$3:$B$7,'Salary vs Rating.'!$C$3:$C$7) -> 3
A15: Jagajeet Viraj | B15: Female | C15: Website | D15: 31 | E15: 44084 | F15: 41980 | G15: Average | H15: india | I15: =TODAY() -> 45585 | J15: =All_Staff[[#This Row],[current date]]-All_Staff[[#This Row],[Date Joined]] -> 1501 | K15: =All_Staff[[#This Row],[tunure]]/365 -> 4.1123288 | L15: =IF(All_Staff[[#This Row],[tunure in year]]>3,3%,2%)*All_Staff[[#This Row],[Salary]] -> 1259.4 | M15: =_xlfn.XLOOKUP(All_Staff[[#This Row],[Rating]],'Salary vs Rating.'!$B$3:$B$7,'Salary vs Rating.'!$C$3:$C$7) -> 3
A16: Drusy MacCombe | B16: Male | C16: Sales | D16: 28 | E16: 44820 | F16: 43510 | G16: Very poor | H16: NZ | I16: =TODAY() -> 45585 | J16: =All_Staff[[#This Row],[current date]]-All_Staff[[#This Row],[Date Joined]] -> 765 | K16: =All_Staff[[#This Row],[tunure]]/365 -> 2.0958904 | L16: =IF(All_Staff[[#This Row],[tunure in year]]>3,3%,2%)*All_Staff[[#This Row],[Salary]] -> 870.2 | M16: =_xlfn.XLOOKUP(All_Staff[[#This Row],[Rating]],'Salary vs Rating.'!$B$3:$B$7,'Salary vs Rating.'!$C$3:$C$7) -> 1 | O16: 2
A17: Rupak Mehra | B17: Male | C17: Sales | D17: 28 | E17: 44758 | F17: 43510 | G17: Very poor | H17: india | I17: =TODAY() -> 45585 | J17: =All_Staff[[#This Row],[current date]]-All_Staff[[#This Row],[Date Joined]] -> 827 | K17: =All_Staff[[#This Row],[tunure]]/365 -> 2.2657534 | L17: =IF(All_Staff[[#This Row],[tunure in year]]>3,3%,2%)*All_Staff[[#This Row],[Salary]] -> 870.2 | M17: =_xlfn.XLOOKUP(All_Staff[[#This Row],[Rating]],'Salary vs Rating.'!$B$3:$B$7,'Salary vs Rating.'!$C$3:$C$7) -> 1 | P17: Orton Livick | Q17: {=_xlfn.XLOOKUP(P17,All_Staff[Name],All_Staff[])} -> Orton Livick | R17: Male | S17: Procurement | T17: 21 | U17: 44104 | V17: 37920 | W17: Average | X17: NZ | Y17: 45585 | Z17: 1481 | AA17: 4.0575342 | AB17: 1137.6 | AC17: 3
A18: Kassi Jonson | B18: Female | C18: Website | D18: 32 | E18: 44354 | F18: 43840 | G18: Above average | H18: NZ | I18: =TODAY() -> 45585 | J18: =All_Staff[[#This Row],[current date]]-All_Staff[[#This Row],[Date Joined]] -> 1231 | K18: =All_Staff[[#This Row],[tunure]]/365 -> 3.3726027 | L18: =IF(All_Staff[[#This Row],[tunure in year]]>3,3%,2%)*All_Staff[[#This Row],[Salary]] -> 1315.2 | M18: =_xlfn.XLOOKUP(All_Staff[[#This Row],[Rating]],'Salary vs Rating.'!$B$3:$B$7,'Salary vs Rating.'!$C$3:$C$7) -> 4 | Q18: =VLOOKUP(P17,All_Staff[],5) -> 44529
A19: Yagna Sujeev | B19: Female | C19: Website | D19: 32 | E19: 44293 | F19: 43840 | G19: Above average | H19: india | I19: =TODAY() -> 45585 | J19: =All_Staff[[#This Row],[current date]]-All_Staff[[#This Row],[Date Joined]] -> 1292 | K19: =All_Staff[[#This Row],[tunure]]/365 -> 3.539726 | L19: =IF(All_Staff[[#This Row],[tunure in year]]>3,3%,2%)*All_Staff[[#This Row],[Salary]] -> 1315.2 | M19: =_xlfn.XLOOKUP(All_Staff[[#This Row],[Rating]],'Salary vs Rating.'!$B$3:$B$7,'Salary vs Rating.'!$C$3:$C$7) -> 4 | Q19: =LOOKUP(P17,All_Staff[]) -> 3
A20: Florinda Crace | B20: Female | C20: HR | D20: 32 | E20: 44400 | F20: 45510 | G20: Average | H20: NZ | I20: =TODAY() -> 45585 | J20: =All_Staff[[#This Row],[current date]]-All_Staff[[#This Row],[Date Joined]] -> 1185 | K20: =All_Staff[[#This Row],[tunure]]/365 -> 3.2465753 | L20: =IF(All_Staff[[#This Row],[tunure in year]]>3,3%,2%)*All_Staff[[#This Row],[Salary]] -> 1365.3 | M20: =_xlfn.XLOOKUP(All_Staff[[#This Row],[Rating]],'Salary vs Rating.'!$B$3:$B$7,'Salary vs Rating.'!$C$3:$C$7) -> 3
A21: Madhavdas Buhpathi | B21: Female | C21: HR | D21: 32 | E21: 44339 | F21: 45510 | G21: Average | H21: india | I21: =TODAY() -> 45585 | J21: =All_Staff[[#This Row],[current date]]-All_Staff[[#This Row],[Date Joined]] -> 1246 | K21: =All_Staff[[#This Row],[tunure]]/365 -> 3.4136986 | L21: =IF(All_Staff[[#This Row],[tunure in year]]>3,3%,2%)*All_Staff[[#This Row],[Salary]] -> 1365.3 | M21: =_xlfn.XLOOKUP(All_Staff[[#This Row],[Rating]],'Salary vs Rating.'!$B$3:$B$7,'Salary vs Rating.'!$C$3:$C$7) -> 3
A22: Dell Molloy | B22: Male | C22: Procurement | D22: 26 | E22: 44225 | F22: 47360 | G22: Average | H22: NZ | I22: =TODAY() -> 45585 | J22: =All_Staff[[#This Row],[current date]]-All_Staff[[#This Row],[Date Joined]] -> 1360 | K22: =All_Staff[[#This Row],[tunure]]/365 -> 3.7260274 | L22: =IF(All_Staff[[#This Row],[tunure in year]]>3,3%,2%)*All_Staff[[#This Row],[Salary]] -> 1420.8 | M22: =_xlfn.XLOOKUP(All_Staff[[#This Row],[Rating]],'Salary vs Rating.'!$B$3:$B$7,'Salary vs Rating.'!$C$3:$C$7) -> 3 | P22: =IF(All_Staff[[#This Row],[tunure in year]]>3,3%,2%) -> 0.03
A23: Shiuli Sapna | B23: Male | C23: Procurement | D23: 26 | E23: 44164 | F23: 47360 | G23: Average | H23: india | I23: =TODAY() -> 45585 | J23: =All_Staff[[#This Row],[current date]]-All_Staff[[#This Row],[Date Joined]] -> 1421 | K23: =All_Staff[[#This Row],[tunure]]/365 -> 3.8931507 | L23: =IF(All_Staff[[#This Row],[tunure in year]]>3,3%,2%)*All_Staff[[#This Row],[Salary]] -> 1420.8 | M23: =_xlfn.XLOOKUP(All_Staff[[#This Row],[Rating]],'Salary vs Rating.'!$B$3:$B$7,'Salary vs Rating.'!$C$3:$C$7) -> 3
A24: Jan Morforth | B24: Male | C24: Finance | D24: 28 | E24: 44041 | F24: 48170 | G24: Above average | H24: NZ | I24: =TODAY() -> 45585 | J24: =All_Staff[[#This Row],[current date]]-All_Staff[[#This Row],[Date Joined]] -> 1544 | K24: =All_Staff[[#This Row],[tunure]]/365 -> 4.230137 | L24: =IF(All_Staff[[#This Row],[tunure in year]]>3,3%,2%)*All_Staff[[#This Row],[Salary]] -> 1445.1 | M24: =_xlfn.XLOOKUP(All_Staff[[#This Row],[Rating]],'Salary vs Rating.'!$B$3:$B$7,'Salary vs Rating.'!$C$3:$C$7) -> 4
A25: Ardhendu Abhichandra Jayakar | B25: Male | C25: Finance | D25: 28 | E25: 43980 | F25: 48170 | G25: Above average | H25: india | I25: =TODAY() -> 45585 | J25: =All_Staff[[#This Row],[current date]]-All_Staff[[#This Row],[Date Joined]] -> 1605 | K25: =All_Staff[[#This Row],[tunure]]/365 -> 4.3972603 | L25: =IF(All_Staff[[#This Row],[tunure in year]]>3,3%,2%)*All_Staff[[#This Row],[Salary]] -> 1445.1 | M25: =_xlfn.XLOOKUP(All_Staff[[#This Row],[Rating]],'Salary vs Rating.'!$B$3:$B$7,'Salary vs Rating.'!$C$3:$C$7) -> 4
A26: Erin Androsik | B26: Male | C26: Procurement | D26: 33 | E26: 44701 | F26: 48530 | G26: Above average | H26: NZ | I26: =TODAY() -> 45585 | J26: =All_Staff[[#This Row],[current date]]-All_Staff[[#This Row],[Date Joined]] -> 884 | K26: =All_Staff[[#This Row],[tunure]]/365 -> 2.4219178 | L26: =IF(All_Staff[[#This Row],[tunure in year]]>3,3%,2%)*All_Staff[[#This Row],[Salary]] -> 970.6 | M26: =_xlfn.XLOOKUP(All_Staff[[#This Row],[Rating]],'Salary vs Rating.'!$B$3:$B$7,'Salary vs Rating.'!$C$3:$C$7) -> 4
A27: Piyali Mahanthapa | B27: Male | C27: Procurement | D27: 33 | E27: 44640 | F27: 48530 | G27: Above average | H27: india | I27: =TODAY() -> 45585 | J27: =All_Staff[[#This Row],[current date]]-All_Staff[[#This Row],[Date Joined]] -> 945 | K27: =All_Staff[[#This Row],[tunure]]/365 -> 2.5890411 | L27: =IF(All_Staff[[#This Row],[tunure in year]]>3,3%,2%)*All_Staff[[#This Row],[Salary]] -> 970.6 | M27: =_xlfn.XLOOKUP(All_Staff[[#This Row],[Rating]],'Salary vs Rating.'!$B$3:$B$7,'Salary vs Rating.'!$C$3:$C$7) -> 4
A28: Gunar Cockshoot | B28: Male | C28: Website | D28: 31 | E28: 44511 | F28: 48950 | G28: Average | H28: NZ | I28: =TODAY() -> 45585 | J28: =All_Staff[[#This Row],[current date]]-All_Staff[[#This Row],[Date Joined]] -> 1074 | K28: =All_Staff[[#This Row],[tunure]]/365 -> 2.9424658 | L28: =IF(All_Staff[[#This Row],[tunure in year]]>3,3%,2%)*All_Staff[[#This Row],[Salary]] -> 979 | M28: =_xlfn.XLOOKUP(All_Staff[[#This Row],[Rating]],'Salary vs Rating.'!$B$3:$B$7,'Salary vs Rating.'!$C$3:$C$7) -> 3
A29: Amal Nimesh | B29: Male | C29: Website | D29: 31 | E29: 44450 | F29: 48950 | G29: Average | H29: india | I29: =TODAY() -> 45585 | J29: =All_Staff[[#This Row],[current date]]-All_Staff[[#This Row],[Date Joined]] -> 1135 | K29: =All_Staff[[#This Row],[tunure]]/365 -> 3.109589 | L29: =IF(All_Staff[[#This Row],[tunure in year]]>3,3%,2%)*All_Staff[[#This Row],[Salary]] -> 1468.5 | M29: =_xlfn.XLOOKUP(All_Staff[[#This Row],[Rating]],'Salary vs Rating.'!$B$3:$B$7,'Salary vs Rating.'!$C$3:$C$7) -> 3
A30: Esmaria Denecamp | B30: Male | C30: Finance | D30: 27 | E30: 44567 | F30: 48980 | G30: Average | H30: NZ | I30: =TODAY() -> 45585 | J30: =All_Staff[[#This Row],[current date]]-All_Staff[[#This Row],[Date Joined]] -> 1018 | K30: =All_Staff[[#This Row],[tunure]]/365 -> 2.7890411 | L30: =IF(All_Staff[[#This Row],[tunure in year]]>3,3%,2%)*All_Staff[[#This Row],[Salary]] -> 979.6 | M30: =_xlfn.XLOOKUP(All_Staff[[#This Row],[Rating]],'Salary vs Rating.'!$B$3:$B$7,'Salary vs Rating.'!$C$3:$C$7) -> 3
A31: Vanmala Shriharsha | B31: Male | C31: Finance | D31: 27 | E31: 44506 | F31: 48980 | G31: Average | H31: india | I31: =TODAY() -> 45585 | J31: =All_Staff[[#This Row],[current date]]-All_Staff[[#This Row],[Date Joined]] -> 1079 | K31: =All_Staff[[#This Row],[tunure]]/365 -> 2.9561644 | L31: =IF(All_Staff[[#This Row],[tunure in year]]>3,3%,2%)*All_Staff[[#This Row],[Salary]] -> 979.6 | M31: =_xlfn.XLOOKUP(All_Staff[[#This Row],[Rating]],'Salary vs Rating.'!$B$3:$B$7,'Salary vs Rating.'!$C$3:$C$7) -> 3
A32: Violante Courtonne | B32: Female | C32: Sales | D32: 34 | E32: 44721 | F32: 49630 | G32: Poor | H32: NZ | I32: =TODAY() -> 45585 | J32: =All_Staff[[#This Row],[current date]]-All_Staff[[#This Row],[Date Joined]] -> 864 | K32: =All_Staff[[#This Row],[tunure]]/365 -> 2.3671233 | L32: =IF(All_Staff[[#This Row],[tunure in year]]>3,3%,2%)*All_Staff[[#This Row],[Salary]] -> 992.6 | M32: =_xlfn.XLOOKUP(All_Staff[[#This Row],[Rating]],'Salary vs Rating.'!$B$3:$B$7,'Salary vs Rating.'!$C$3:$C$7) -> 2
A33: Daruka Ghazali | B33: Female | C33: Sales | D33: 34 | E33: 44660 | F33: 49630 | G33: Poor | H33: india | I33: =TODAY() -> 45585 | J33: =All_Staff[[#This Row],[current date]]-All_Staff[[#This Row],[Date Joined]] -> 925 | K33: =All_Staff[[#This Row],[tunure]]/365 -> 2.5342466 | L33: =IF(All_Staff[[#This Row],[tunure in year]]>3,3%,2%)*All_Staff[[#This Row],[Salary]] -> 992.6 | M33: =_xlfn.XLOOKUP(All_Staff[[#This Row],[Rating]],'Salary vs Rating.'!$B$3:$B$7,'Salary vs Rating.'!$C$3:$C$7) -> 2
A34: Kaye Crocroft | B34: Male | C34: Finance | D34: 24 | E34: 44436 | F34: 52610 | G34: Poor | H34: NZ | I34: =TODAY() -> 45585 | J34: =All_Staff[[#This Row],[current date]]-All_Staff[[#This Row],[Date Joined]] -> 1149 | K34: =All_Staff[[#This Row],[tunure]]/365 -> 3.1479452 | L34: =IF(All_Staff[[#This Row],[tunure in year]]>3,3%,2%)*All_Staff[[#This Row],[Salary]] -> 1578.3 | M34: =_xlfn.XLOOKUP(All_Staff[[#This Row],[Rating]],'Salary vs Rating.'!$B$3:$B$7,'Salary vs Rating.'!$C$3:$C$7) -> 2
... A185: Anjushri Chandiramani | B185: Female | C185: HR | D185: 27 | E185: 44061 | F185: 119110 | G185: Average | H185: india | I185: =TODAY() -> 45585 | J185: =All_Staff[[#This Row],[current date]]-All_Staff[[#This Row],[Date Joined]] -> 1524 | K185: =All_Staff[[#This Row],[tunure]]/365 -> 4.1753425 | L185: =IF(All_Staff[[#This Row],[tunure in year]]>3,3%,2%)*All_Staff[[#This Row],[Salary]] -> 3573.3 | M185: =_xlfn.XLOOKUP(All_Staff[[#This Row],[Rating]],'Salary vs Rating.'!$B$3:$B$7,'Salary vs Rating.'!$C$3:$C$7) -> 3

Sheet Salary vs Rating
A3: Row Labels | B3: Count of Name | C3: Average of Salary
A4: Exceptional | B4: 4 | C4: 92080
A5: Above average | B5: 20 | C5: 75933
A6: Average | B6: 138 | C6: 77058.551
A7: Poor | B7: 16 | C7: 78115
A8: Very poor | B8: 6 | C8: 77423.333
A9: Grand Total | B9: 184 | C9: 77366.522

Sheet Salary vs Rating.
B3: Exceptional | C3: 5
B4: Above average | C4: 4
B5: Average | C5: 3
B6: Poor | C6: 2
B7: Very poor | C7: 1

Sheet employee trend
B4: Row Labels | C4: Count of Name
B5: 2020 | C5: 37
B6: 2021 | C6: 82
B7: 2022 | C7: 63
B8: 2023 | C8: 2
B9: Grand Total | C9: 184

Sheet NZ vs India
B1: Country | C1: All | E1: Country | F1: All
B3: Row Labels | C3: Count of Name | E3: Row Labels | F3: Count of Name
B4: Procurement | C4: 56 | E4: Procurement | F4: 56
B5: Website | C5: 54 | E5: Website | F5: 54
B6: Finance | C6: 38 | E6: Finance | F6: 38
B7: Sales | C7: 28 | E7: Sales | F7: 28
B8: HR | C8: 8 | E8: HR | F8: 8
B9: Grand Total | C9: 184 | E9: Grand Total | F9: 184

Sheet salary spread

Sheet male vs female
B3: Column Labels
A4: Values | B4: Female | C4: Male
A5: Count of Name | B5: 86 | C5: 90
A6: Average of Age | B6: 31.406977 | C6: 29.444444
A7: Average of Salary | B7: 78284.186 | C7: 75334.444

Sheet info finder
B3: 3 | C3: info finder
B5: Dep name | C5: Procurement
B6: 1 | C6: 2 | D6: 3 | E6: 4 | F6: 5 | G6: 6 | H6: 7 | I6: 8 | J6: 9 | K6: 10 | L6: 11
B7: {=_xlfn._xlws.FILTER(All_Staff[],All_Staff[Department]=C5)} -> #VALUE! | N7: {=_xlfn._xlws.SORT(_xlfn.CHOOSECOLS(_xlfn._xlws.FILTER(All_Staff[],All_Staff[Department]=C5),1,3,6),3,-1)} -> Roddy Speechley | O7: Procurement | P7: 115920
N8: Sarayu Ragunathan | O8: Procurement | P8: 115920
N9: Tracy Renad | O9: Procurement | P9: 114890
N10: Dhruv Manjunath | O10: Procurement | P10: 114890
N11: Hogan Iles | O11: Procurement | P11: 114180
N12: Sarojini Naueshwara | O12: Procurement | P12: 114180
N13: Mahalia Larcher | O13: Procurement | P13: 113280
N14: Ilesh Dasgupta | O14: Procurement | P14: 113280
N15: Mollie Hanway | O15: Procurement | P15: 112650
N16: Bandhula Sathyanna | O16: Procurement | P16: 112650
N17: Halimeda Kuscha | O17: Procurement | P17: 112570
N18: Makshi Vinutha | O18: Procurement | P18: 112570
N19: Madelene Upcott | O19: Procurement | P19: 109190
... N62: Akbar Sorabhjee | O62: Procurement | P62: 37920

Sheet Card
B2: NZ | I2: India
B3: =COUNTIF(All_Staff[Country],"NZ") -> 92 | D3: =COUNTIFS(All_Staff[Country],"NZ",All_Staff[Gender],"Female") -> 43 | F3: =AVERAGEIFS(All_Staff[Salary],All_Staff[Country],"NZ") -> 77366.522 | I3: =COUNTIF(All_Staff[Country],"india") -> 92 | K3: =COUNTIFS(All_Staff[Country],"india",All_Staff[Gender],"Female") -> 43 | M3: =AVERAGEIFS(All_Staff[Salary],All_Staff[Country],"india") -> 77366.522
D5: Headcount by department
